<?xml version="1.0" encoding="utf-8"?>
<robot name="Robot">
  <link name="Chassis">
    <inertial>
      <origin xyz="0.0754502137597999 0.0991092619435655 0.161107514233835" rpy="0 0 0" />
      <mass value="2.07180345206185" />
      <inertia ixx="0.00356945572688469" ixy="5.11137365474242E-21" ixz="1.20613262152867E-19" iyy="0.00884981333361377" iyz="8.34099270000998E-20" izz="0.0088548831534792" />
    </inertial>
    <visual>
      <origin xyz="0 0 0" rpy="0 0 0" />
      <geometry>
        <mesh filename="package://Robot/visualSTL/Chassis.STL" />
      </geometry>
      <material name="0000FF">
        <color rgba="255 0 0 1" />
      </material>
    </visual>
    <collision>
      <origin xyz="0 0 0" rpy="0 0 0" />
      <geometry>
        <mesh filename="package://Robot/collisionSTL/Chassis.STL" />
      </geometry>
    </collision>
  </link>
  <link name="FL Wheel">
    <inertial>
      <origin xyz="0 0 0.0976075142338346" rpy="0 0 0" />
      <mass value="0.202708327012954" />
      <inertia ixx="0.000143721006239312" ixy="4.95496177213446E-40" ixz="2.60749908296803E-37" iyy="0.000143721006239312" iyz="2.94447559556559E-37" izz="0.000265645461769345" />
    </inertial>
    <visual>
      <origin xyz="-0.1516502137598 -0.0733936843274657 0" rpy="0 0 0" />
      <geometry>
        <mesh filename="package://Robot/visualSTL/FL Wheel.STL" />
      </geometry>
      <material name="00FF80">
        <color rgba="128 255 0 1" />
      </material>
    </visual>
    <collision>
      <origin xyz="-0.1516502137598 -0.0733936843274657 0" rpy="0 0 0" />
      <geometry>
        <mesh filename="package://Robot/collisionSTL/FL Wheel.STL" />
      </geometry>
    </collision>
  </link>
  <link name="FR Wheel">
    <inertial>
      <origin xyz="0 -2.77555756156289E-17 0.224607514233835" rpy="0 0 0" />
      <mass value="0.202708327012954" />
      <inertia ixx="0.000143721006239312" ixy="4.95496177212916E-40" ixz="2.60749908296803E-37" iyy="0.000143721006239312" iyz="1.8627532974539E-36" izz="0.000265645461769345" />
    </inertial>
    <visual>
      <origin xyz="-0.1516502137598 -0.0733936843274657 0" rpy="0 0 0" />
      <geometry>
        <mesh filename="package://Robot/visualSTL/FR Wheel.STL" />
      </geometry>
      <material name="00FF80">
        <color rgba="128 255 0 1" />
      </material>
    </visual>
    <collision>
      <origin xyz="-0.1516502137598 -0.0733936843274657 0" rpy="0 0 0" />
      <geometry>
        <mesh filename="package://Robot/collisionSTL/FR Wheel.STL" />
      </geometry>
    </collision>
  </link>
  <link name="RL Wheel">
    <inertial>
      <origin xyz="0 0 0.0976075142338346" rpy="0 0 0" />
      <mass value="0.202708327012954" />
      <inertia ixx="0.000143721006239312" ixy="4.95496177213446E-40" ixz="2.60749908296803E-37" iyy="0.000143721006239312" iyz="2.94447559556559E-37" izz="0.000265645461769345" />
    </inertial>
    <visual>
      <origin xyz="0.00074978624020014 -0.0733936843274657 0" rpy="0 0 0" />
      <geometry>
        <mesh filename="package://Robot/visualSTL/RL Wheel.STL" />
      </geometry>
      <material name="00FF80">
        <color rgba="128 255 0 1" />
      </material>
    </visual>
    <collision>
      <origin xyz="0.00074978624020014 -0.0733936843274657 0" rpy="0 0 0" />
      <geometry>
        <mesh filename="package://Robot/collisionSTL/RL Wheel.STL" />
      </geometry>
    </collision>
  </link>
  <link name="RR Wheel">
    <inertial>
      <origin xyz="0 0 0.224607514233835" rpy="0 0 0" />
      <mass value="0.202708327012954" />
      <inertia ixx="0.000143721006239312" ixy="4.95496177212916E-40" ixz="2.60749908296803E-37" iyy="0.000143721006239312" iyz="1.8627532974539E-36" izz="0.000265645461769345" />
    </inertial>
    <visual>
      <origin xyz="0.00074978624020014 -0.0733936843274657 0" rpy="0 0 0" />
      <geometry>
        <mesh filename="package://Robot/visualSTL/RR Wheel.STL" />
      </geometry>
      <material name="00FF80">
        <color rgba="128 255 0 1" />
      </material>
    </visual>
    <collision>
      <origin xyz="0.00074978624020014 -0.0733936843274657 0" rpy="0 0 0" />
      <geometry>
        <mesh filename="package://Robot/collisionSTL/RR Wheel.STL" />
      </geometry>
    </collision>
  </link>
  <joint name="Chassis-FL Wheel" type="continuous">
    <origin xyz="0.1516502137598 0.0733936843274657 0" rpy="0 0 0" />
    <parent link="Chassis" />
    <child link="FL Wheel" />
    <axis xyz="0 0 -1" />
  </joint>
  <joint name="Chassis-FR Wheel" type="continuous">
    <origin xyz="0.1516502137598 0.0733936843274657 0" rpy="0 0 0" />
    <parent link="Chassis" />
    <child link="FR Wheel" />
    <axis xyz="0 0 -1" />
  </joint>
  <joint name="Chassis-RL Wheel" type="continuous">
    <origin xyz="-0.00074978624020014 0.0733936843274657 0" rpy="0 0 0" />
    <parent link="Chassis" />
    <child link="RL Wheel" />
    <axis xyz="0 0 -1" />
  </joint>
  <joint name="Chassis-RR Wheel" type="continuous">
    <origin xyz="-0.00074978624020014 0.0733936843274657 0" rpy="0 0 0" />
    <parent link="Chassis" />
    <child link="RR Wheel" />
    <axis xyz="0 0 -1" />
  </joint>
</robot>